Workbook

Sheet Dashboard
B2: Latest MRR | D2: Latest Customer | F2: Avg Churn % | H2: Avg LTV
B3: =KPIs!B19 -> 3900 | D3: =KPIs!D19 -> 21 | F3: =AVERAGE(KPIs!F3:F19) -> 0.16536942 | H3: =AVERAGE(KPIs!I3:I19) -> 2648.9061

Sheet Forecast
A1: Assumptions
A2: Starting Customers | D2: 21 | F2: Scenario | G2: New Cust | H2: Churn | I2: APRU | K2: Tier | L2: CAC | M2: MRR
A3: Starting MRR | D3: 3900 | F3: Base | G3: 9 | H3: 0.1654 | I3: 185.7 | K3: Basic | L3: 30 | M3: 50
A4: ARPU | D4: 185 | F4: Best | G4: 15 | H4: 0.1 | I4: 195 | K4: Pro | L4: 100 | M4: 200
A5: Tot new cust | D5: 9 | F5: Worst | G5: 3 | H5: 0.25 | I5: 175 | K5: Enterprise | L5: 200 | M5: 500
A6: Monthly New Basic Customers | D6: 0.32
A7: Monthly new Pro Customer | D7: 0.34
A8: Monthly New Enterprise Cust. | D8: 0.34
A9: Monthly Churn Rate | D9: 0.17
A10: Monthly CAC | D10: 110
A11: Forecast Months | D11: 12
A15: Month | B15: Start Cust | C15: New Basic | D15: New Pro | E15: New Enterprise | F15: Churned Cust | G15: End Cust | H15: ARPU | I15: MRR | J15: CAC Spend | K15: Net Rev Growth
A16: =DATE(2025,7,1) -> 45839 | B16: =$D$2 -> 21 | C16: =ROUND($D$6*$D$5,0) -> 3 | D16: =ROUND($D$7*$D$5,0) -> 3 | E16: =ROUND($D$8*$D$5,0) -> 3 | F16: =ROUND(B16*$D$9,0) -> 4 | G16: =B16+(C16+D16+E16)-F16 -> 26 | H16: =$D$4 -> 185 | I16: =G16*H16 -> 4810 | J16: {=SUMPRODUCT(C16:E16,TRANSPOSE($L$3:$L$5))} -> 990 | K16: =I16-D3 -> 910
A17: =EDATE(A16,1) -> 45870 | B17: =G16 -> 26 | C17: =ROUND($D$6*$D$5,0) -> 3 | D17: =ROUND($D$7*$D$5,0) -> 3 | E17: =ROUND($D$8*$D$5,0) -> 3 | F17: =ROUND(B17*$D$9,0) -> 4 | G17: =B17+(C17+D17+E17)-F17 -> 31 | H17: =$D$4 -> 185 | I17: =G17*H17 -> 5735 | J17: {=SUMPRODUCT(C17:E17,TRANSPOSE($L$3:$L$5))} -> 990 | K17: =I17-I16 -> 925
A18: =EDATE(A17,1) -> 45901 | B18: =G17 -> 31 | C18: =ROUND($D$6*$D$5,0) -> 3 | D18: =ROUND($D$7*$D$5,0) -> 3 | E18: =ROUND($D$8*$D$5,0) -> 3 | F18: =ROUND(B18*$D$9,0) -> 5 | G18: =B18+(C18+D18+E18)-F18 -> 35 | H18: =$D$4 -> 185 | I18: =G18*H18 -> 6475 | J18: {=SUMPRODUCT(C18:E18,TRANSPOSE($L$3:$L$5))} -> 990 | K18: =I18-I17 -> 740
A19: =EDATE(A18,1) -> 45931 | B19: =G18 -> 35 | C19: =ROUND($D$6*$D$5,0) -> 3 | D19: =ROUND($D$7*$D$5,0) -> 3 | E19: =ROUND($D$8*$D$5,0) -> 3 | F19: =ROUND(B19*$D$9,0) -> 6 | G19: =B19+(C19+D19+E19)-F19 -> 38 | H19: =$D$4 -> 185 | I19: =G19*H19 -> 7030 | J19: {=SUMPRODUCT(C19:E19,TRANSPOSE($L$3:$L$5))} -> 990 | K19: =I19-I18 -> 555
A20: =EDATE(A19,1) -> 45962 | B20: =G19 -> 38 | C20: =ROUND($D$6*$D$5,0) -> 3 | D20: =ROUND($D$7*$D$5,0) -> 3 | E20: =ROUND($D$8*$D$5,0) -> 3 | F20: =ROUND(B20*$D$9,0) -> 6 | G20: =B20+(C20+D20+E20)-F20 -> 41 | H20: =$D$4 -> 185 | I20: =G20*H20 -> 7585 | J20: {=SUMPRODUCT(C20:E20,TRANSPOSE($L$3:$L$5))} -> 990 | K20: =I20-I19 -> 555
A21: =EDATE(A20,1) -> 45992 | B21: =G20 -> 41 | C21: =ROUND($D$6*$D$5,0) -> 3 | D21: =ROUND($D$7*$D$5,0) -> 3 | E21: =ROUND($D$8*$D$5,0) -> 3 | F21: =ROUND(B21*$D$9,0) -> 7 | G21: =B21+(C21+D21+E21)-F21 -> 43 | H21: =$D$4 -> 185 | I21: =G21*H21 -> 7955 | J21: {=SUMPRODUCT(C21:E21,TRANSPOSE($L$3:$L$5))} -> 990 | K21: =I21-I20 -> 370
A22: =EDATE(A21,1) -> 46023 | B22: =G21 -> 43 | C22: =ROUND($D$6*$D$5,0) -> 3 | D22: =ROUND($D$7*$D$5,0) -> 3 | E22: =ROUND($D$8*$D$5,0) -> 3 | F22: =ROUND(B22*$D$9,0) -> 7 | G22: =B22+(C22+D22+E22)-F22 -> 45 | H22: =$D$4 -> 185 | I22: =G22*H22 -> 8325 | J22: {=SUMPRODUCT(C22:E22,TRANSPOSE($L$3:$L$5))} -> 990 | K22: =I22-I21 -> 370
A23: =EDATE(A22,1) -> 46054 | B23: =G22 -> 45 | C23: =ROUND($D$6*$D$5,0) -> 3 | D23: =ROUND($D$7*$D$5,0) -> 3 | E23: =ROUND($D$8*$D$5,0) -> 3 | F23: =ROUND(B23*$D$9,0) -> 8 | G23: =B23+(C23+D23+E23)-F23 -> 46 | H23: =$D$4 -> 185 | I23: =G23*H23 -> 8510 | J23: {=SUMPRODUCT(C23:E23,TRANSPOSE($L$3:$L$5))} -> 990 | K23: =I23-I22 -> 185
A24: =EDATE(A23,1) -> 46082 | B24: =G23 -> 46 | C24: =ROUND($D$6*$D$5,0) -> 3 | D24: =ROUND($D$7*$D$5,0) -> 3 | E24: =ROUND($D$8*$D$5,0) -> 3 | F24: =ROUND(B24*$D$9,0) -> 8 | G24: =B24+(C24+D24+E24)-F24 -> 47 | H24: =$D$4 -> 185 | I24: =G24*H24 -> 8695 | J24: {=SUMPRODUCT(C24:E24,TRANSPOSE($L$3:$L$5))} -> 990 | K24: =I24-I23 -> 185
A25: =EDATE(A24,1) -> 46113 | B25: =G24 -> 47 | C25: =ROUND($D$6*$D$5,0) -> 3 | D25: =ROUND($D$7*$D$5,0) -> 3 | E25: =ROUND($D$8*$D$5,0) -> 3 | F25: =ROUND(B25*$D$9,0) -> 8 | G25: =B25+(C25+D25+E25)-F25 -> 48 | H25: =$D$4 -> 185 | I25: =G25*H25 -> 8880 | J25: {=SUMPRODUCT(C25:E25,TRANSPOSE($L$3:$L$5))} -> 990 | K25: =I25-I24 -> 185
A26: =EDATE(A25,1) -> 46143 | B26: =G25 -> 48 | C26: =ROUND($D$6*$D$5,0) -> 3 | D26: =ROUND($D$7*$D$5,0) -> 3 | E26: =ROUND($D$8*$D$5,0) -> 3 | F26: =ROUND(B26*$D$9,0) -> 8 | G26: =B26+(C26+D26+E26)-F26 -> 49 | H26: =$D$4 -> 185 | I26: =G26*H26 -> 9065 | J26: {=SUMPRODUCT(C26:E26,TRANSPOSE($L$3:$L$5))} -> 990 | K26: =I26-I25 -> 185
A27: =EDATE(A26,1) -> 46174 | B27: =G26 -> 49 | C27: =ROUND($D$6*$D$5,0) -> 3 | D27: =ROUND($D$7*$D$5,0) -> 3 | E27: =ROUND($D$8*$D$5,0) -> 3 | F27: =ROUND(B27*$D$9,0) -> 8 | G27: =B27+(C27+D27+E27)-F27 -> 50 | H27: =$D$4 -> 185 | I27: =G27*H27 -> 9250 | J27: {=SUMPRODUCT(C27:E27,TRANSPOSE($L$3:$L$5))} -> 990 | K27: =I27-I26 -> 185
A28: =EDATE(A27,1) -> 46204 | B28: =G27 -> 50 | C28: =ROUND($D$6*$D$5,0) -> 3 | D28: =ROUND($D$7*$D$5,0) -> 3 | E28: =ROUND($D$8*$D$5,0) -> 3 | F28: =ROUND(B28*$D$9,0) -> 9 | G28: =B28+(C28+D28+E28)-F28 -> 50 | H28: =$D$4 -> 185 | I28: =G28*H28 -> 9250 | J28: {=SUMPRODUCT(C28:E28,TRANSPOSE($L$3:$L$5))} -> 990 | K28: =I28-I27 -> 0
A31: Month | B31: Base MRR | C31: Best MRR | D31: Worst MRR | E31: Selected MRR | G31: Scenarios
A32: =DATE(2025,7,1) -> 45839 | B32: 4828.2 | C32: 6630 | D32: 3325 | E32: =IF($G$32="Base",B32,IF($G$32="Best",C32,D32)) -> 3325 | G32: Worst
A33: =EDATE(A32,1) -> 45870 | B33: 5756.7 | C33: 8970 | D33: 2975 | E33: =IF($G$32="Base",B33,IF($G$32="Best",C33,D33)) -> 2975
A34: =EDATE(A33,1) -> 45901 | B34: 6499.5 | C34: 10920 | D34: 2800 | E34: =IF($G$32="Base",B34,IF($G$32="Best",C34,D34)) -> 2800
A35: =EDATE(A34,1) -> 45931 | B35: 7056.6 | C35: 12675 | D35: 2625 | E35: =IF($G$32="Base",B35,IF($G$32="Best",C35,D35)) -> 2625
A36: =EDATE(A35,1) -> 45962 | B36: 7613.7 | C36: 14235 | D36: 2450 | E36: =IF($G$32="Base",B36,IF($G$32="Best",C36,D36)) -> 2450
A37: =EDATE(A36,1) -> 45992 | B37: 7985.1 | C37: 15795 | D37: 2275 | E37: =IF($G$32="Base",B37,IF($G$32="Best",C37,D37)) -> 2275
A38: =EDATE(A37,1) -> 46023 | B38: 8356.5 | C38: 17160 | D38: 2275 | E38: =IF($G$32="Base",B38,IF($G$32="Best",C38,D38)) -> 2275
A39: =EDATE(A38,1) -> 46054 | B39: 8542.2 | C39: 18330 | D39: 2275 | E39: =IF($G$32="Base",B39,IF($G$32="Best",C39,D39)) -> 2275
A40: =EDATE(A39,1) -> 46082 | B40: 8727.9 | C40: 19500 | D40: 2275 | E40: =IF($G$32="Base",B40,IF($G$32="Best",C40,D40)) -> 2275
A41: =EDATE(A40,1) -> 46113 | B41: 8913.6 | C41: 20475 | D41: 2275 | E41: =IF($G$32="Base",B41,IF($G$32="Best",C41,D41)) -> 2275
A42: =EDATE(A41,1) -> 46143 | B42: 9099.3 | C42: 21255 | D42: 2275 | E42: =IF($G$32="Base",B42,IF($G$32="Best",C42,D42)) -> 2275
A43: =EDATE(A42,1) -> 46174 | B43: 9285 | C43: 22035 | D43: 2275 | E43: =IF($G$32="Base",B43,IF($G$32="Best",C43,D43)) -> 2275
A44: =EDATE(A43,1) -> 46204 | B44: 9285 | C44: 22815 | D44: 2275 | E44: =IF($G$32="Base",B44,IF($G$32="Best",C44,D44)) -> 2275
E64: =$G$32 & " Case MRR Forecast" -> Worst Case MRR Forecast

Sheet KPIs
A1: month_date | B1: MRR | C1: ARR | D1: Active_Customers | E1: # Churn | F1: Churn % | G1: AVG CAC | H1: ARPU | I1: LTV | J1: Growrth_Rate | K1: New customer | L1: LTV/CAC | M1: Revenue Loss from Churn
A2: 45292 | B2: =SUMIFS(revenue_Clean!C:C,revenue_Clean!F:F,A2) -> 1850 | C2: =B2*12 -> 22200 | D2: =COUNTIFS(revenue_Clean!F:F,A2) -> 10 | E2: =COUNTIFS(customer_clean!G:G,"Churned",customer_clean!H:H,A2) -> 0 | G2: =AVERAGE(customer_clean!E:E) -> 110.11 | H2: =B2/D2 -> 185 | I2: =IF(F2=0,0,H2/F2) -> 0 | L2: =I2/G2 -> 0 | M2: =E2*H2 -> 0
A3: 45323 | B3: =SUMIFS(revenue_Clean!C:C,revenue_Clean!F:F,A3) -> 4600 | C3: =B3*12 -> 55200 | D3: =COUNTIFS(revenue_Clean!F:F,A3) -> 17 | E3: =COUNTIFS(customer_clean!G:G,"Churned",customer_clean!H:H,A3) -> 1 | F3: =E3/D2 -> 0.1 | G3: =AVERAGE(customer_clean!E:E) -> 110.11 | H3: =B3/D3 -> 270.58824 | I3: =IF(F3=0,0,H3/F3) -> 2705.8824 | J3: =(D3-D2)/D3 -> 0.41176471 | K3: =D3-D2+E3 -> 8 | L3: =I3/G3 -> 24.574356 | M3: =E3*H3 -> 270.58824
A4: 45352 | B4: =SUMIFS(revenue_Clean!C:C,revenue_Clean!F:F,A4) -> 7650 | C4: =B4*12 -> 91800 | D4: =COUNTIFS(revenue_Clean!F:F,A4) -> 30 | E4: =COUNTIFS(customer_clean!G:G,"Churned",customer_clean!H:H,A4) -> 0 | F4: =E4/D3 -> 0 | G4: =AVERAGE(customer_clean!E:E) -> 110.11 | H4: =B4/D4 -> 255 | I4: =IF(F4=0,0,H4/F4) -> 0 | J4: =(D4-D3)/D4 -> 0.43333333 | K4: =D4-D3+E4 -> 13 | L4: =I4/G4 -> 0 | M4: =E4*H4 -> 0
A5: 45383 | B5: =SUMIFS(revenue_Clean!C:C,revenue_Clean!F:F,A5) -> 9600 | C5: =B5*12 -> 115200 | D5: =COUNTIFS(revenue_Clean!F:F,A5) -> 39 | E5: =COUNTIFS(customer_clean!G:G,"Churned",customer_clean!H:H,A5) -> 1 | F5: =E5/D4 -> 0.033333333 | G5: =AVERAGE(customer_clean!E:E) -> 110.11 | H5: =B5/D5 -> 246.15385 | I5: =IF(F5=0,0,H5/F5) -> 7384.6154 | J5: =(D5-D4)/D5 -> 0.23076923 | K5: =D5-D4+E5 -> 10 | L5: =I5/G5 -> 67.065801 | M5: =E5*H5 -> 246.15385
A6: 45413 | B6: =SUMIFS(revenue_Clean!C:C,revenue_Clean!F:F,A6) -> 11750 | C6: =B6*12 -> 141000 | D6: =COUNTIFS(revenue_Clean!F:F,A6) -> 49 | E6: =COUNTIFS(customer_clean!G:G,"Churned",customer_clean!H:H,A6) -> 2 | F6: =E6/D5 -> 0.051282051 | G6: =AVERAGE(customer_clean!E:E) -> 110.11 | H6: =B6/D6 -> 239.79592 | I6: =IF(F6=0,0,H6/F6) -> 4676.0204 | J6: =(D6-D5)/D6 -> 0.20408163 | K6: =D6-D5+E6 -> 12 | L6: =I6/G6 -> 42.46681 | M6: =E6*H6 -> 479.59184
A7: 45444 | B7: =SUMIFS(revenue_Clean!C:C,revenue_Clean!F:F,A7) -> 12700 | C7: =B7*12 -> 152400 | D7: =COUNTIFS(revenue_Clean!F:F,A7) -> 53 | E7: =COUNTIFS(customer_clean!G:G,"Churned",customer_clean!H:H,A7) -> 5 | F7: =E7/D6 -> 0.10204082 | G7: =AVERAGE(customer_clean!E:E) -> 110.11 | H7: =B7/D7 -> 239.62264 | I7: =IF(F7=0,0,H7/F7) -> 2348.3019 | J7: =(D7-D6)/D7 -> 0.075471698 | K7: =D7-D6+E7 -> 9 | L7: =I7/G7 -> 21.326872 | M7: =E7*H7 -> 1198.1132
A8: 45474 | B8: =SUMIFS(revenue_Clean!C:C,revenue_Clean!F:F,A8) -> 15900 | C8: =B8*12 -> 190800 | D8: =COUNTIFS(revenue_Clean!F:F,A8) -> 60 | E8: =COUNTIFS(customer_clean!G:G,"Churned",customer_clean!H:H,A8) -> 4 | F8: =E8/D7 -> 0.075471698 | G8: =AVERAGE(customer_clean!E:E) -> 110.11 | H8: =B8/D8 -> 265 | I8: =IF(F8=0,0,H8/F8) -> 3511.25 | J8: =(D8-D7)/D8 -> 0.11666667 | K8: =D8-D7+E8 -> 11 | L8: =I8/G8 -> 31.888566 | M8: =E8*H8 -> 1060
A9: 45505 | B9: =SUMIFS(revenue_Clean!C:C,revenue_Clean!F:F,A9) -> 17800 | C9: =B9*12 -> 213600 | D9: =COUNTIFS(revenue_Clean!F:F,A9) -> 65 | E9: =COUNTIFS(customer_clean!G:G,"Churned",customer_clean!H:H,A9) -> 4 | F9: =E9/D8 -> 0.066666667 | G9: =AVERAGE(customer_clean!E:E) -> 110.11 | H9: =B9/D9 -> 273.84615 | I9: =IF(F9=0,0,H9/F9) -> 4107.6923 | J9: =(D9-D8)/D9 -> 0.076923077 | K9: =D9-D8+E9 -> 9 | L9: =I9/G9 -> 37.305352 | M9: =E9*H9 -> 1095.3846
A10: 45536 | B10: =SUMIFS(revenue_Clean!C:C,revenue_Clean!F:F,A10) -> 17150 | C10: =B10*12 -> 205800 | D10: =COUNTIFS(revenue_Clean!F:F,A10) -> 64 | E10: =COUNTIFS(customer_clean!G:G,"Churned",customer_clean!H:H,A10) -> 6 | F10: =E10/D9 -> 0.092307692 | G10: =AVERAGE(customer_clean!E:E) -> 110.11 | H10: =B10/D10 -> 267.96875 | I10: =IF(F10=0,0,H10/F10) -> 2902.9948 | J10: =(D10-D9)/D10 -> -0.015625 | K10: =D10-D9+E10 -> 5 | L10: =I10/G10 -> 26.364497 | M10: =E10*H10 -> 1607.8125
A11: 45566 | B11: =SUMIFS(revenue_Clean!C:C,revenue_Clean!F:F,A11) -> 18750 | C11: =B11*12 -> 225000 | D11: =COUNTIFS(revenue_Clean!F:F,A11) -> 72 | E11: =COUNTIFS(customer_clean!G:G,"Churned",customer_clean!H:H,A11) -> 6 | F11: =E11/D10 -> 0.09375 | G11: =AVERAGE(customer_clean!E:E) -> 110.11 | H11: =B11/D11 -> 260.41667 | I11: =IF(F11=0,0,H11/F11) -> 2777.7778 | J11: =(D11-D10)/D11 -> 0.11111111 | K11: =D11-D10+E11 -> 14 | L11: =I11/G11 -> 25.227298 | M11: =E11*H11 -> 1562.5
A12: 45597 | B12: =SUMIFS(revenue_Clean!C:C,revenue_Clean!F:F,A12) -> 17900 | C12: =B12*12 -> 214800 | D12: =COUNTIFS(revenue_Clean!F:F,A12) -> 70 | E12: =COUNTIFS(customer_clean!G:G,"Churned",customer_clean!H:H,A12) -> 8 | F12: =E12/D11 -> 0.11111111 | G12: =AVERAGE(customer_clean!E:E) -> 110.11 | H12: =B12/D12 -> 255.71429 | I12: =IF(F12=0,0,H12/F12) -> 2301.4286 | J12: =(D12-D11)/D12 -> -0.028571429 | K12: =D12-D11+E12 -> 6 | L12: =I12/G12 -> 20.901177 | M12: =E12*H12 -> 2045.7143
A13: 45627 | B13: =SUMIFS(revenue_Clean!C:C,revenue_Clean!F:F,A13) -> 19300 | C13: =B13*12 -> 231600 | D13: =COUNTIFS(revenue_Clean!F:F,A13) -> 74 | E13: =COUNTIFS(customer_clean!G:G,"Churned",customer_clean!H:H,A13) -> 6 | F13: =E13/D12 -> 0.085714286 | G13: =AVERAGE(customer_clean!E:E) -> 110.11 | H13: =B13/D13 -> 260.81081 | I13: =IF(F13=0,0,H13/F13) -> 3042.7928 | J13: =(D13-D12)/D13 -> 0.054054054 | K13: =D13-D12+E13 -> 10 | L13: =I13/G13 -> 27.634119 | M13: =E13*H13 -> 1564.8649
A14: 45658 | B14: =SUMIFS(revenue_Clean!C:C,revenue_Clean!F:F,A14) -> 20800 | C14: =B14*12 -> 249600 | D14: =COUNTIFS(revenue_Clean!F:F,A14) -> 80 | E14: =COUNTIFS(customer_clean!G:G,"Churned",customer_clean!H:H,A14) -> 6 | F14: =E14/D13 -> 0.081081081 | G14: =AVERAGE(customer_clean!E:E) -> 110.11 | H14: =B14/D14 -> 260 | I14: =IF(F14=0,0,H14/F14) -> 3206.6667 | J14: =(D14-D13)/D14 -> 0.075 | K14: =D14-D13+E14 -> 12 | L14: =I14/G14 -> 29.122393 | M14: =E14*H14 -> 1560
... A19: 45809 | B19: =SUMIFS(revenue_Clean!C:C,revenue_Clean!F:F,A19) -> 3900 | C19: =B19*12 -> 46800 | D19: =COUNTIFS(revenue_Clean!F:F,A19) -> 21 | E19: =COUNTIFS(customer_clean!G:G,"Churned",customer_clean!H:H,A19) -> 41 | F19: =E19/D18 -> 0.93181818 | G19: =AVERAGE(customer_clean!E:E) -> 110.11 | H19: =B19/D19 -> 185.71429 | I19: =IF(F19=0,0,H19/F19) -> 199.30314 | J19: =(D19-D18)/D19 -> -1.0952381 | K19: =D19-D18+E19 -> 18 | L19: =I19/G19 -> 1.8100367 | M19: =E19*H19 -> 7614.2857
A24: month_date | B24: # Pro | C24: #Basic | D24: #Enterprise | E24: Pro Rev | F24: Basic Rev | G24: Ent Rev | H24: CAC Pro | I24: CAC Basic | J24: CAC Entr | K24: % Pro | L24: %Basic | M24: %Entrp.
A25: 45292 | B25: =COUNTIFS(subs_clean!$C:$C,KPIs!A25,subs_clean!$E:$E,"Pro") -> 3 | C25: =COUNTIFS(subs_clean!$C:$C,$A$25,subs_clean!$E:$E,"Enterprise") -> 2 | D25: =COUNTIFS(subs_clean!$C:$C,$A$25,subs_clean!$E:$E,"Basic") -> 5 | E25: =B25*200 -> 600 | F25: =C25*50 -> 100 | G25: =D25*500 -> 2500 | H25: =B25*100 -> 300 | I25: =C25*30 -> 60 | J25: =200*D25 -> 1000 | K25: =B25/(SUM(B25:D25)) -> 0.3 | L25: =C25/(SUM(B25:D25)) -> 0.2 | M25: =D25/SUM(B25:D25) -> 0.5
A26: 45323 | B26: =COUNTIFS(subs_clean!$C:$C,KPIs!A26,subs_clean!$E:$E,"Pro") -> 4 | C26: =COUNTIFS(subs_clean!$C:$C,$A26,subs_clean!$E:$E,"Basic") -> 6 | D26: =COUNTIFS(subs_clean!$C:$C,A26,subs_clean!$E:$E,"Basic") -> 6 | E26: =B26*200 -> 800 | F26: =C26*50 -> 300 | G26: =D26*500 -> 3000 | H26: =B26*100 -> 400 | I26: =C26*30 -> 180 | J26: =200*D26 -> 1200 | K26: =B26/(SUM(B26:D26)) -> 0.25 | L26: =C26/(SUM(B26:D26)) -> 0.375 | M26: =D26/SUM(B26:D26) -> 0.375
A27: 45352 | B27: =COUNTIFS(subs_clean!$C:$C,KPIs!A27,subs_clean!$E:$E,"Pro") -> 11 | C27: =COUNTIFS(subs_clean!$C:$C,$A27,subs_clean!$E:$E,"Basic") -> 9 | D27: =COUNTIFS(subs_clean!$C:$C,A27,subs_clean!$E:$E,"Basic") -> 9 | E27: =B27*200 -> 2200 | F27: =C27*50 -> 450 | G27: =D27*500 -> 4500 | H27: =B27*100 -> 1100 | I27: =C27*30 -> 270 | J27: =200*D27 -> 1800 | K27: =B27/(SUM(B27:D27)) -> 0.37931034 | L27: =C27/(SUM(B27:D27)) -> 0.31034483 | M27: =D27/SUM(B27:D27) -> 0.31034483
A28: 45383 | B28: =COUNTIFS(subs_clean!$C:$C,KPIs!A28,subs_clean!$E:$E,"Pro") -> 15 | C28: =COUNTIFS(subs_clean!$C:$C,$A28,subs_clean!$E:$E,"Basic") -> 12 | D28: =COUNTIFS(subs_clean!$C:$C,A28,subs_clean!$E:$E,"Basic") -> 12 | E28: =B28*200 -> 3000 | F28: =C28*50 -> 600 | G28: =D28*500 -> 6000 | H28: =B28*100 -> 1500 | I28: =C28*30 -> 360 | J28: =200*D28 -> 2400 | K28: =B28/(SUM(B28:D28)) -> 0.38461538 | L28: =C28/(SUM(B28:D28)) -> 0.30769231 | M28: =D28/SUM(B28:D28) -> 0.30769231
A29: 45413 | B29: =COUNTIFS(subs_clean!$C:$C,KPIs!A29,subs_clean!$E:$E,"Pro") -> 20 | C29: =COUNTIFS(subs_clean!$C:$C,$A29,subs_clean!$E:$E,"Basic") -> 15 | D29: =COUNTIFS(subs_clean!$C:$C,A29,subs_clean!$E:$E,"Basic") -> 15 | E29: =B29*200 -> 4000 | F29: =C29*50 -> 750 | G29: =D29*500 -> 7500 | H29: =B29*100 -> 2000 | I29: =C29*30 -> 450 | J29: =200*D29 -> 3000 | K29: =B29/(SUM(B29:D29)) -> 0.4 | L29: =C29/(SUM(B29:D29)) -> 0.3 | M29: =D29/SUM(B29:D29) -> 0.3
A30: 45444 | B30: =COUNTIFS(subs_clean!$C:$C,KPIs!A30,subs_clean!$E:$E,"Pro") -> 22 | C30: =COUNTIFS(subs_clean!$C:$C,$A30,subs_clean!$E:$E,"Basic") -> 16 | D30: =COUNTIFS(subs_clean!$C:$C,A30,subs_clean!$E:$E,"Basic") -> 16 | E30: =B30*200 -> 4400 | F30: =C30*50 -> 800 | G30: =D30*500 -> 8000 | H30: =B30*100 -> 2200 | I30: =C30*30 -> 480 | J30: =200*D30 -> 3200 | K30: =B30/(SUM(B30:D30)) -> 0.40740741 | L30: =C30/(SUM(B30:D30)) -> 0.2962963 | M30: =D30/SUM(B30:D30) -> 0.2962963
A31: 45474 | B31: =COUNTIFS(subs_clean!$C:$C,KPIs!A31,subs_clean!$E:$E,"Pro") -> 23 | C31: =COUNTIFS(subs_clean!$C:$C,$A31,subs_clean!$E:$E,"Basic") -> 16 | D31: =COUNTIFS(subs_clean!$C:$C,A31,subs_clean!$E:$E,"Basic") -> 16 | E31: =B31*200 -> 4600 | F31: =C31*50 -> 800 | G31: =D31*500 -> 8000 | H31: =B31*100 -> 2300 | I31: =C31*30 -> 480 | J31: =200*D31 -> 3200 | K31: =B31/(SUM(B31:D31)) -> 0.41818182 | L31: =C31/(SUM(B31:D31)) -> 0.29090909 | M31: =D31/SUM(B31:D31) -> 0.29090909
A32: 45505 | B32: =COUNTIFS(subs_clean!$C:$C,KPIs!A32,subs_clean!$E:$E,"Pro") -> 22 | C32: =COUNTIFS(subs_clean!$C:$C,$A32,subs_clean!$E:$E,"Basic") -> 18 | D32: =COUNTIFS(subs_clean!$C:$C,A32,subs_clean!$E:$E,"Basic") -> 18 | E32: =B32*200 -> 4400 | F32: =C32*50 -> 900 | G32: =D32*500 -> 9000 | H32: =B32*100 -> 2200 | I32: =C32*30 -> 540 | J32: =200*D32 -> 3600 | K32: =B32/(SUM(B32:D32)) -> 0.37931034 | L32: =C32/(SUM(B32:D32)) -> 0.31034483 | M32: =D32/SUM(B32:D32) -> 0.31034483
A33: 45536 | B33: =COUNTIFS(subs_clean!$C:$C,KPIs!A33,subs_clean!$E:$E,"Pro") -> 21 | C33: =COUNTIFS(subs_clean!$C:$C,$A33,subs_clean!$E:$E,"Basic") -> 19 | D33: =COUNTIFS(subs_clean!$C:$C,A33,subs_clean!$E:$E,"Basic") -> 19 | E33: =B33*200 -> 4200 | F33: =C33*50 -> 950 | G33: =D33*500 -> 9500 | H33: =B33*100 -> 2100 | I33: =C33*30 -> 570 | J33: =200*D33 -> 3800 | K33: =B33/(SUM(B33:D33)) -> 0.3559322 | L33: =C33/(SUM(B33:D33)) -> 0.3220339 | M33: =D33/SUM(B33:D33) -> 0.3220339
A34: 45566 | B34: =COUNTIFS(subs_clean!$C:$C,KPIs!A34,subs_clean!$E:$E,"Pro") -> 23 | C34: =COUNTIFS(subs_clean!$C:$C,$A34,subs_clean!$E:$E,"Basic") -> 23 | D34: =COUNTIFS(subs_clean!$C:$C,A34,subs_clean!$E:$E,"Basic") -> 23 | E34: =B34*200 -> 4600 | F34: =C34*50 -> 1150 | G34: =D34*500 -> 11500 | H34: =B34*100 -> 2300 | I34: =C34*30 -> 690 | J34: =200*D34 -> 4600 | K34: =B34/(SUM(B34:D34)) -> 0.33333333 | L34: =C34/(SUM(B34:D34)) -> 0.33333333 | M34: =D34/SUM(B34:D34) -> 0.33333333
A35: 45597 | B35: =COUNTIFS(subs_clean!$C:$C,KPIs!A35,subs_clean!$E:$E,"Pro") -> 24 | C35: =COUNTIFS(subs_clean!$C:$C,$A35,subs_clean!$E:$E,"Basic") -> 22 | D35: =COUNTIFS(subs_clean!$C:$C,A35,subs_clean!$E:$E,"Basic") -> 22 | E35: =B35*200 -> 4800 | F35: =C35*50 -> 1100 | G35: =D35*500 -> 11000 | H35: =B35*100 -> 2400 | I35: =C35*30 -> 660 | J35: =200*D35 -> 4400 | K35: =B35/(SUM(B35:D35)) -> 0.35294118 | L35: =C35/(SUM(B35:D35)) -> 0.32352941 | M35: =D35/SUM(B35:D35) -> 0.32352941
A36: 45627 | B36: =COUNTIFS(subs_clean!$C:$C,KPIs!A36,subs_clean!$E:$E,"Pro") -> 26 | C36: =COUNTIFS(subs_clean!$C:$C,$A36,subs_clean!$E:$E,"Basic") -> 22 | D36: =COUNTIFS(subs_clean!$C:$C,A36,subs_clean!$E:$E,"Basic") -> 22 | E36: =B36*200 -> 5200 | F36: =C36*50 -> 1100 | G36: =D36*500 -> 11000 | H36: =B36*100 -> 2600 | I36: =C36*30 -> 660 | J36: =200*D36 -> 4400 | K36: =B36/(SUM(B36:D36)) -> 0.37142857 | L36: =C36/(SUM(B36:D36)) -> 0.31428571 | M36: =D36/SUM(B36:D36) -> 0.31428571
A37: 45658 | B37: =COUNTIFS(subs_clean!$C:$C,KPIs!A37,subs_clean!$E:$E,"Pro") -> 25 | C37: =COUNTIFS(subs_clean!$C:$C,$A37,subs_clean!$E:$E,"Basic") -> 26 | D37: =COUNTIFS(subs_clean!$C:$C,A37,subs_clean!$E:$E,"Basic") -> 26 | E37: =B37*200 -> 5000 | F37: =C37*50 -> 1300 | G37: =D37*500 -> 13000 | H37: =B37*100 -> 2500 | I37: =C37*30 -> 780 | J37: =200*D37 -> 5200 | K37: =B37/(SUM(B37:D37)) -> 0.32467532 | L37: =C37/(SUM(B37:D37)) -> 0.33766234 | M37: =D37/SUM(B37:D37) -> 0.33766234
... A42: 45809 | B42: =COUNTIFS(subs_clean!$C:$C,KPIs!A42,subs_clean!$E:$E,"Pro") -> 7 | C42: =COUNTIFS(subs_clean!$C:$C,$A42,subs_clean!$E:$E,"Basic") -> 10 | D42: =COUNTIFS(subs_clean!$C:$C,A42,subs_clean!$E:$E,"Basic") -> 10 | E42: =B42*200 -> 1400 | F42: =C42*50 -> 500 | G42: =D42*500 -> 5000 | H42: =B42*100 -> 700 | I42: =C42*30 -> 300 | J42: =200*D42 -> 2000 | K42: =B42/(SUM(B42:D42)) -> 0.25925926 | L42: =C42/(SUM(B42:D42)) -> 0.37037037 | M42: =D42/SUM(B42:D42) -> 0.37037037
A44: Total | B44: =SUM(KPIs!$B$25:$B$42) -> 334 | C44: =SUM(KPIs!$C$25:$C$42) -> 317 | D44: =SUM(KPIs!$D$25:$D$42) -> 320 | E44: =SUM(KPIs!$E$25:$E$42) -> 66800 | F44: =SUM(KPIs!$F$25:$F$42) -> 15850 | G44: =SUM(KPIs!$G$25:$G$42) -> 160000 | H44: =SUM(KPIs!$H$25:$H$42) -> 33400 | I44: =SUM(KPIs!$I$25:$I$42) -> 9510 | J44: =SUM(KPIs!$J$25:$J$42) -> 64000 | K44: =SUM(KPIs!$K$25:$K$42) -> 6.1528659 | L44: =SUM(KPIs!$L$25:$L$42) -> 5.773567 | M44: =SUM(KPIs!$M$25:$M$42) -> 6.073567

Sheet customer_clean
A1: customer_id | B1: signup_date | C1: plan_type | D1: monthly_fee | E1: acquisition_cost | F1: churn_date | G1: status | H1: Churn_Month | J1: Churned
A2: 1001 | B2: 45603 | C2: Basic | D2: 50 | E2: 30 | G2: =IF(F2="","Active","Churned") -> Active | H2: =IF(F2="","",DATE(YEAR(F2),MONTH(F2),1)) | J2: =IF(G2="Churned",1,0) -> 0
A3: 1002 | B3: 45449 | C3: Basic | D3: 50 | E3: 30 | G3: =IF(F3="","Active","Churned") -> Active | H3: =IF(F3="","",DATE(YEAR(F3),MONTH(F3),1)) | J3: =IF(G3="Churned",1,0) -> 0
A4: 1003 | B4: 45657 | C4: Basic | D4: 50 | E4: 30 | G4: =IF(F4="","Active","Churned") -> Active | H4: =IF(F4="","",DATE(YEAR(F4),MONTH(F4),1)) | J4: =IF(G4="Churned",1,0) -> 0
A5: 1004 | B5: 45617 | C5: Pro | D5: 200 | E5: 100 | G5: =IF(F5="","Active","Churned") -> Active | H5: =IF(F5="","",DATE(YEAR(F5),MONTH(F5),1)) | J5: =IF(G5="Churned",1,0) -> 0
A6: 1005 | B6: 45520 | C6: Pro | D6: 200 | E6: 100 | G6: =IF(F6="","Active","Churned") -> Active | H6: =IF(F6="","",DATE(YEAR(F6),MONTH(F6),1)) | J6: =IF(G6="Churned",1,0) -> 0
A7: 1006 | B7: 45606 | C7: Basic | D7: 50 | E7: 30 | G7: =IF(F7="","Active","Churned") -> Active | H7: =IF(F7="","",DATE(YEAR(F7),MONTH(F7),1)) | J7: =IF(G7="Churned",1,0) -> 0
A8: 1007 | B8: 45363 | C8: Enterprise | D8: 500 | E8: 200 | G8: =IF(F8="","Active","Churned") -> Active | H8: =IF(F8="","",DATE(YEAR(F8),MONTH(F8),1)) | J8: =IF(G8="Churned",1,0) -> 0
A9: 1008 | B9: 45605 | C9: Pro | D9: 200 | E9: 100 | G9: =IF(F9="","Active","Churned") -> Active | H9: =IF(F9="","",DATE(YEAR(F9),MONTH(F9),1)) | J9: =IF(G9="Churned",1,0) -> 0
A10: 1009 | B10: 45520 | C10: Pro | D10: 200 | E10: 100 | G10: =IF(F10="","Active","Churned") -> Active | H10: =IF(F10="","",DATE(YEAR(F10),MONTH(F10),1)) | J10: =IF(G10="Churned",1,0) -> 0
A11: 1010 | B11: 45754 | C11: Pro | D11: 200 | E11: 100 | G11: =IF(F11="","Active","Churned") -> Active | H11: =IF(F11="","",DATE(YEAR(F11),MONTH(F11),1)) | J11: =IF(G11="Churned",1,0) -> 0
A12: 1011 | B12: 45747 | C12: Basic | D12: 50 | E12: 30 | G12: =IF(F12="","Active","Churned") -> Active | H12: =IF(F12="","",DATE(YEAR(F12),MONTH(F12),1)) | J12: =IF(G12="Churned",1,0) -> 0
A13: 1012 | B13: 45712 | C13: Enterprise | D13: 500 | E13: 200 | G13: =IF(F13="","Active","Churned") -> Active | H13: =IF(F13="","",DATE(YEAR(F13),MONTH(F13),1)) | J13: =IF(G13="Churned",1,0) -> 0
... A20: 1019 | B20: 45472 | C20: Basic | D20: 50 | E20: 30 | G20: =IF(F20="","Active","Churned") -> Active | H20: =IF(F20="","",DATE(YEAR(F20),MONTH(F20),1)) | J20: =IF(G20="Churned",1,0) -> 0
A21: 1020 | B21: 45578 | C21: Pro | D21: 200 | E21: 100 | F21: 45785 | G21: =IF(F21="","Active","Churned") -> Churned | H21: =IF(F21="","",DATE(YEAR(F21),MONTH(F21),1)) -> 45778 | J21: =IF(G21="Churned",1,0) -> 1
A22: 1021 | B22: 45411 | C22: Pro | D22: 200 | E22: 100 | F22: 45464 | G22: =IF(F22="","Active","Churned") -> Churned | H22: =IF(F22="","",DATE(YEAR(F22),MONTH(F22),1)) -> 45444 | J22: =IF(G22="Churned",1,0) -> 1
A23: 1022 | B23: 45373 | C23: Enterprise | D23: 500 | E23: 200 | G23: =IF(F23="","Active","Churned") -> Active | H23: =IF(F23="","",DATE(YEAR(F23),MONTH(F23),1)) | J23: =IF(G23="Churned",1,0) -> 0
A24: 1023 | B24: 45641 | C24: Basic | D24: 50 | E24: 30 | F24: 45831 | G24: =IF(F24="","Active","Churned") -> Churned | H24: =IF(F24="","",DATE(YEAR(F24),MONTH(F24),1)) -> 45809 | J24: =IF(G24="Churned",1,0) -> 1
A25: 1024 | B25: 45587 | C25: Basic | D25: 50 | E25: 30 | G25: =IF(F25="","Active","Churned") -> Active | H25: =IF(F25="","",DATE(YEAR(F25),MONTH(F25),1)) | J25: =IF(G25="Churned",1,0) -> 0
A26: 1025 | B26: 45364 | C26: Enterprise | D26: 500 | E26: 200 | G26: =IF(F26="","Active","Churned") -> Active | H26: =IF(F26="","",DATE(YEAR(F26),MONTH(F26),1)) | J26: =IF(G26="Churned",1,0) -> 0
A27: 1026 | B27: 45743 | C27: Pro | D27: 200 | E27: 100 | F27: 45818 | G27: =IF(F27="","Active","Churned") -> Churned | H27: =IF(F27="","",DATE(YEAR(F27),MONTH(F27),1)) -> 45809 | J27: =IF(G27="Churned",1,0) -> 1
A28: 1027 | B28: 45455 | C28: Pro | D28: 200 | E28: 100 | G28: =IF(F28="","Active","Churned") -> Active | H28: =IF(F28="","",DATE(YEAR(F28),MONTH(F28),1)) | J28: =IF(G28="Churned",1,0) -> 0
A29: 1028 | B29: 45670 | C29: Enterprise | D29: 500 | E29: 200 | G29: =IF(F29="","Active","Churned") -> Active | H29: =IF(F29="","",DATE(YEAR(F29),MONTH(F29),1)) | J29: =IF(G29="Churned",1,0) -> 0
A30: 1029 | B30: 45833 | C30: Enterprise | D30: 500 | E30: 200 | G30: =IF(F30="","Active","Churned") -> Active | H30: =IF(F30="","",DATE(YEAR(F30),MONTH(F30),1)) | J30: =IF(G30="Churned",1,0) -> 0
A31: 1030 | B31: 45614 | C31: Enterprise | D31: 500 | E31: 200 | G31: =IF(F31="","Active","Churned") -> Active | H31: =IF(F31="","",DATE(YEAR(F31),MONTH(F31),1)) | J31: =IF(G31="Churned",1,0) -> 0
A32: 1031 | B32: 45390 | C32: Pro | D32: 200 | E32: 100 | F32: 45640 | G32: =IF(F32="","Active","Churned") -> Churned | H32: =IF(F32="","",DATE(YEAR(F32),MONTH(F32),1)) -> 45627 | J32: =IF(G32="Churned",1,0) -> 1
A33: 1032 | B33: 45692 | C33: Pro | D33: 200 | E33: 100 | G33: =IF(F33="","Active","Churned") -> Active | H33: =IF(F33="","",DATE(YEAR(F33),MONTH(F33),1)) | J33: =IF(G33="Churned",1,0) -> 0
A34: 1033 | B34: 45723 | C34: Basic | D34: 50 | E34: 30 | G34: =IF(F34="","Active","Churned") -> Active | H34: =IF(F34="","",DATE(YEAR(F34),MONTH(F34),1)) | J34: =IF(G34="Churned",1,0) -> 0
A35: 1034 | B35: 45388 | C35: Basic | D35: 50 | E35: 30 | F35: 45753 | G35: =IF(F35="","Active","Churned") -> Churned | H35: =IF(F35="","",DATE(YEAR(F35),MONTH(F35),1)) -> 45748 | J35: =IF(G35="Churned",1,0) -> 1
A36: 1035 | B36: 45504 | C36: Basic | D36: 50 | E36: 30 | F36: 45779 | G36: =IF(F36="","Active","Churned") -> Churned | H36: =IF(F36="","",DATE(YEAR(F36),MONTH(F36),1)) -> 45778 | J36: =IF(G36="Churned",1,0) -> 1
A37: 1036 | B37: 45419 | C37: Enterprise | D37: 500 | E37: 200 | G37: =IF(F37="","Active","Churned") -> Active | H37: =IF(F37="","",DATE(YEAR(F37),MONTH(F37),1)) | J37: =IF(G37="Churned",1,0) -> 0
A38: 1037 | B38: 45626 | C38: Pro | D38: 200 | E38: 100 | G38: =IF(F38="","Active","Churned") -> Active | H38: =IF(F38="","",DATE(YEAR(F38),MONTH(F38),1)) | J38: =IF(G38="Churned",1,0) -> 0
A39: 1038 | B39: 45319 | C39: Enterprise | D39: 500 | E39: 200 | G39: =IF(F39="","Active","Churned") -> Active | H39: =IF(F39="","",DATE(YEAR(F39),MONTH(F39),1)) | J39: =IF(G39="Churned",1,0) -> 0
A40: 1039 | B40: 45769 | C40: Basic | D40: 50 | E40: 30 | G40: =IF(F40="","Active","Churned") -> Active | H40: =IF(F40="","",DATE(YEAR(F40),MONTH(F40),1)) | J40: =IF(G40="Churned",1,0) -> 0
A41: 1040 | B41: 45428 | C41: Enterprise | D41: 500 | E41: 200 | G41: =IF(F41="","Active","Churned") -> Active | H41: =IF(F41="","",DATE(YEAR(F41),MONTH(F41),1)) | J41: =IF(G41="Churned",1,0) -> 0
A42: 1041 | B42: 45464 | C42: Pro | D42: 200 | E42: 100 | G42: =IF(F42="","Active","Churned") -> Active | H42: =IF(F42="","",DATE(YEAR(F42),MONTH(F42),1)) | J42: =IF(G42="Churned",1,0) -> 0
A43: 1042 | B43: 45400 | C43: Pro | D43: 200 | E43: 100 | F43: 45735 | G43: =IF(F43="","Active","Churned") -> Churned | H43: =IF(F43="","",DATE(YEAR(F43),MONTH(F43),1)) -> 45717 | J43: =IF(G43="Churned",1,0) -> 1
A44: 1043 | B44: 45684 | C44: Enterprise | D44: 500 | E44: 200 | F44: 45727 | G44: =IF(F44="","Active","Churned") -> Churned | H44: =IF(F44="","",DATE(YEAR(F44),MONTH(F44),1)) -> 45717 | J44: =IF(G44="Churned",1,0) -> 1
A45: 1044 | B45: 45716 | C45: Pro | D45: 200 | E45: 100 | G45: =IF(F45="","Active","Churned") -> Active | H45: =IF(F45="","",DATE(YEAR(F45),MONTH(F45),1)) | J45: =IF(G45="Churned",1,0) -> 0
A46: 1045 | B46: 45838 | C46: Pro | D46: 200 | E46: 100 | G46: =IF(F46="","Active","Churned") -> Active | H46: =IF(F46="","",DATE(YEAR(F46),MONTH(F46),1)) | J46: =IF(G46="Churned",1,0) -> 0
...

Sheet subs_clean
A1: subscription_raw | B1: customer_id | C1: month_date | D1: monthly_fee | E1: Plan_Type | F1: acquisition_cost
A2: S-1020-202410 | B2: 1020 | C2: 45566 | D2: 200 | E2: =_xlfn.XLOOKUP(B2,customer_clean!A:A,customer_clean!C:C) -> Pro | F2: =_xlfn.XLOOKUP(B2,customer_clean!A:A,customer_clean!E:E) -> 100
A3: S-1020-202411 | B3: 1020 | C3: 45597 | D3: 200 | E3: =_xlfn.XLOOKUP(B3,customer_clean!A:A,customer_clean!C:C) -> Pro | F3: =_xlfn.XLOOKUP(B3,customer_clean!A:A,customer_clean!E:E) -> 100
A4: S-1020-202412 | B4: 1020 | C4: 45627 | D4: 200 | E4: =_xlfn.XLOOKUP(B4,customer_clean!A:A,customer_clean!C:C) -> Pro | F4: =_xlfn.XLOOKUP(B4,customer_clean!A:A,customer_clean!E:E) -> 100
A5: S-1020-202501 | B5: 1020 | C5: 45658 | D5: 200 | E5: =_xlfn.XLOOKUP(B5,customer_clean!A:A,customer_clean!C:C) -> Pro | F5: =_xlfn.XLOOKUP(B5,customer_clean!A:A,customer_clean!E:E) -> 100
A6: S-1020-202502 | B6: 1020 | C6: 45689 | D6: 200 | E6: =_xlfn.XLOOKUP(B6,customer_clean!A:A,customer_clean!C:C) -> Pro | F6: =_xlfn.XLOOKUP(B6,customer_clean!A:A,customer_clean!E:E) -> 100
A7: S-1020-202503 | B7: 1020 | C7: 45717 | D7: 200 | E7: =_xlfn.XLOOKUP(B7,customer_clean!A:A,customer_clean!C:C) -> Pro | F7: =_xlfn.XLOOKUP(B7,customer_clean!A:A,customer_clean!E:E) -> 100
A8: S-1020-202504 | B8: 1020 | C8: 45748 | D8: 200 | E8: =_xlfn.XLOOKUP(B8,customer_clean!A:A,customer_clean!C:C) -> Pro | F8: =_xlfn.XLOOKUP(B8,customer_clean!A:A,customer_clean!E:E) -> 100
A9: S-1021-202404 | B9: 1021 | C9: 45383 | D9: 200 | E9: =_xlfn.XLOOKUP(B9,customer_clean!A:A,customer_clean!C:C) -> Pro | F9: =_xlfn.XLOOKUP(B9,customer_clean!A:A,customer_clean!E:E) -> 100
A10: S-1021-202405 | B10: 1021 | C10: 45413 | D10: 200 | E10: =_xlfn.XLOOKUP(B10,customer_clean!A:A,customer_clean!C:C) -> Pro | F10: =_xlfn.XLOOKUP(B10,customer_clean!A:A,customer_clean!E:E) -> 100
A11: S-1023-202412 | B11: 1023 | C11: 45627 | D11: 50 | E11: =_xlfn.XLOOKUP(B11,customer_clean!A:A,customer_clean!C:C) -> Basic | F11: =_xlfn.XLOOKUP(B11,customer_clean!A:A,customer_clean!E:E) -> 30
A12: S-1023-202501 | B12: 1023 | C12: 45658 | D12: 50 | E12: =_xlfn.XLOOKUP(B12,customer_clean!A:A,customer_clean!C:C) -> Basic | F12: =_xlfn.XLOOKUP(B12,customer_clean!A:A,customer_clean!E:E) -> 30
A13: S-1023-202502 | B13: 1023 | C13: 45689 | D13: 50 | E13: =_xlfn.XLOOKUP(B13,customer_clean!A:A,customer_clean!C:C) -> Basic | F13: =_xlfn.XLOOKUP(B13,customer_clean!A:A,customer_clean!E:E) -> 30
... A62: S-1042-202501 | B62: 1042 | C62: 45658 | D62: 200 | E62: =_xlfn.XLOOKUP(B62,customer_clean!A:A,customer_clean!C:C) -> Pro | F62: =_xlfn.XLOOKUP(B62,customer_clean!A:A,customer_clean!E:E) -> 100
A63: S-1042-202502 | B63: 1042 | C63: 45689 | D63: 200 | E63: =_xlfn.XLOOKUP(B63,customer_clean!A:A,customer_clean!C:C) -> Pro | F63: =_xlfn.XLOOKUP(B63,customer_clean!A:A,customer_clean!E:E) -> 100 | I63: Enterprise
A64: S-1042-202503 | B64: 1042 | C64: 45717 | D64: 200 | E64: =_xlfn.XLOOKUP(B64,customer_clean!A:A,customer_clean!C:C) -> Pro | F64: =_xlfn.XLOOKUP(B64,customer_clean!A:A,customer_clean!E:E) -> 100
A65: S-1043-202501 | B65: 1043 | C65: 45658 | D65: 500 | E65: =_xlfn.XLOOKUP(B65,customer_clean!A:A,customer_clean!C:C) -> Enterprise | F65: =_xlfn.XLOOKUP(B65,customer_clean!A:A,customer_clean!E:E) -> 200
A66: S-1043-202502 | B66: 1043 | C66: 45689 | D66: 500 | E66: =_xlfn.XLOOKUP(B66,customer_clean!A:A,customer_clean!C:C) -> Enterprise | F66: =_xlfn.XLOOKUP(B66,customer_clean!A:A,customer_clean!E:E) -> 200
A67: S-1047-202501 | B67: 1047 | C67: 45658 | D67: 50 | E67: =_xlfn.XLOOKUP(B67,customer_clean!A:A,customer_clean!C:C) -> Basic | F67: =_xlfn.XLOOKUP(B67,customer_clean!A:A,customer_clean!E:E) -> 30
A68: S-1047-202502 | B68: 1047 | C68: 45689 | D68: 50 | E68: =_xlfn.XLOOKUP(B68,customer_clean!A:A,customer_clean!C:C) -> Basic | F68: =_xlfn.XLOOKUP(B68,customer_clean!A:A,customer_clean!E:E) -> 30
A69: S-1047-202503 | B69: 1047 | C69: 45717 | D69: 50 | E69: =_xlfn.XLOOKUP(B69,customer_clean!A:A,customer_clean!C:C) -> Basic | F69: =_xlfn.XLOOKUP(B69,customer_clean!A:A,customer_clean!E:E) -> 30
A70: S-1047-202504 | B70: 1047 | C70: 45748 | D70: 50 | E70: =_xlfn.XLOOKUP(B70,customer_clean!A:A,customer_clean!C:C) -> Basic | F70: =_xlfn.XLOOKUP(B70,customer_clean!A:A,customer_clean!E:E) -> 30
A71: S-1056-202410 | B71: 1056 | C71: 45566 | D71: 200 | E71: =_xlfn.XLOOKUP(B71,customer_clean!A:A,customer_clean!C:C) -> Pro | F71: =_xlfn.XLOOKUP(B71,customer_clean!A:A,customer_clean!E:E) -> 100
A72: S-1056-202411 | B72: 1056 | C72: 45597 | D72: 200 | E72: =_xlfn.XLOOKUP(B72,customer_clean!A:A,customer_clean!C:C) -> Pro | F72: =_xlfn.XLOOKUP(B72,customer_clean!A:A,customer_clean!E:E) -> 100
A73: S-1056-202412 | B73: 1056 | C73: 45627 | D73: 200 | E73: =_xlfn.XLOOKUP(B73,customer_clean!A:A,customer_clean!C:C) -> Pro | F73: =_xlfn.XLOOKUP(B73,customer_clean!A:A,customer_clean!E:E) -> 100
A74: S-1060-202503 | B74: 1060 | C74: 45717 | D74: 50 | E74: =_xlfn.XLOOKUP(B74,customer_clean!A:A,customer_clean!C:C) -> Basic | F74: =_xlfn.XLOOKUP(B74,customer_clean!A:A,customer_clean!E:E) -> 30
A75: S-1060-202504 | B75: 1060 | C75: 45748 | D75: 50 | E75: =_xlfn.XLOOKUP(B75,customer_clean!A:A,customer_clean!C:C) -> Basic | F75: =_xlfn.XLOOKUP(B75,customer_clean!A:A,customer_clean!E:E) -> 30
... A989: S-1999-202505 | B989: 1999 | C989: 45778 | D989: 500 | E989: =_xlfn.XLOOKUP(B989,customer_clean!A:A,customer_clean!C:C) -> Enterprise | F989: =_xlfn.XLOOKUP(B989,customer_clean!A:A,customer_clean!E:E) -> 200

Sheet revenue_Clean
A1: subscription_id | B1: customer_id | C1: monthly_fee | D1: revenue_type | E1: amount | F1: month_date
A2: S-1020-202410 | B2: 1020 | C2: 200 | D2: MRR | E2: 200 | F2: 45566
A3: S-1020-202411 | B3: 1020 | C3: 200 | D3: MRR | E3: 200 | F3: 45597
A4: S-1020-202412 | B4: 1020 | C4: 200 | D4: MRR | E4: 200 | F4: 45627
A5: S-1020-202501 | B5: 1020 | C5: 200 | D5: MRR | E5: 200 | F5: 45658
A6: S-1020-202502 | B6: 1020 | C6: 200 | D6: MRR | E6: 200 | F6: 45689
A7: S-1020-202503 | B7: 1020 | C7: 200 | D7: MRR | E7: 200 | F7: 45717
A8: S-1020-202504 | B8: 1020 | C8: 200 | D8: MRR | E8: 200 | F8: 45748
A9: S-1021-202404 | B9: 1021 | C9: 200 | D9: MRR | E9: 200 | F9: 45383
A10: S-1021-202405 | B10: 1021 | C10: 200 | D10: MRR | E10: 200 | F10: 45413
A11: S-1023-202412 | B11: 1023 | C11: 50 | D11: MRR | E11: 50 | F11: 45627
A12: S-1023-202501 | B12: 1023 | C12: 50 | D12: MRR | E12: 50 | F12: 45658
A13: S-1023-202502 | B13: 1023 | C13: 50 | D13: MRR | E13: 50 | F13: 45689
... A989: S-1999-202505 | B989: 1999 | C989: 500 | D989: MRR | E989: 500 | F989: 45778

Sheet subscriptions_raw
A1: subscription_raw | B1: customer_id | C1: month | D1: monthly_fee
A2: S-1020-202410 | B2: 1020 | C2: 2024-10 | D2: 200
A3: S-1020-202411 | B3: 1020 | C3: 2024-11 | D3: 200
A4: S-1020-202412 | B4: 1020 | C4: 2024-12 | D4: 200
A5: S-1020-202501 | B5: 1020 | C5: 2025-01 | D5: 200
A6: S-1020-202502 | B6: 1020 | C6: 2025-02 | D6: 200
A7: S-1020-202503 | B7: 1020 | C7: 2025-03 | D7: 200
A8: S-1020-202504 | B8: 1020 | C8: 2025-04 | D8: 200
A9: S-1021-202404 | B9: 1021 | C9: 2024-04 | D9: 200
A10: S-1021-202405 | B10: 1021 | C10: 2024-05 | D10: 200
A11: S-1023-202412 | B11: 1023 | C11: 2024-12 | D11: 50
A12: S-1023-202501 | B12: 1023 | C12: 2025-01 | D12: 50
A13: S-1023-202502 | B13: 1023 | C13: 2025-02 | D13: 50
... A23: S-1031-202406 | B23: 1031 | C23: 2024-06 | D23: 200
A24: S-1031-202407 | B24: 1031 | C24: 1031 | D24: 200
A25: S-1031-202408 | B25: 1031 | C25: 2024-08 | D25: 200
A26: S-1031-202409 | B26: 1031 | C26: 2024-09 | D26: 200
A27: S-1031-202410 | B27: 1031 | C27: 2024-10 | D27: 200
A28: S-1031-202411 | B28: 1031 | C28: 2024-11 | D28: 200
A29: S-1031-202412 | B29: 1031 | C29: 2024-12 | D29: 200
A30: S-1034-202404 | B30: 1034 | C30: 2024-04 | D30: 50
A31: S-1034-202405 | B31: 1034 | C31: 2024-05 | D31: 50
A32: S-1034-202406 | B32: 1034 | C32: 2024-06 | D32: 50
A33: S-1034-202407 | B33: 1034 | C33: 2024-07 | D33: 50
A34: S-1034-202408 | B34: 1034 | C34: 2024-08 | D34: 50
A35: S-1034-202409 | B35: 1034 | C35: 2024-09 | D35: 50
A36: S-1034-202410 | B36: 1034 | C36: 2024-10 | D36: 50
... A989: S-1999-202505 | B989: 1999 | C989: 2025-05 | D989: 500

Sheet revenue_raw
A1: subscription_id | B1: customer_id | C1: month | D1: monthly_fee | E1: revenue_type | F1: amount
A2: S-1020-202410 | B2: 1020 | C2: 2024-10 | D2: 200 | E2: MRR | F2: 200
A3: S-1020-202411 | B3: 1020 | C3: 2024-11 | D3: 200 | E3: MRR | F3: 200
A4: S-1020-202412 | B4: 1020 | C4: 2024-12 | D4: 200 | E4: MRR | F4: 200
A5: S-1020-202501 | B5: 1020 | C5: 2025-01 | D5: 200 | E5: MRR | F5: 200
A6: S-1020-202502 | B6: 1020 | C6: 2025-02 | D6: 200 | E6: MRR | F6: 200
A7: S-1020-202503 | B7: 1020 | C7: 2025-03 | D7: 200 | E7: MRR | F7: 200
A8: S-1020-202504 | B8: 1020 | C8: 2025-04 | D8: 200 | E8: MRR | F8: 200
A9: S-1021-202404 | B9: 1021 | C9: 2024-04 | D9: 200 | E9: MRR | F9: 200
A10: S-1021-202405 | B10: 1021 | C10: 2024-05 | D10: 200 | E10: MRR | F10: 200
A11: S-1023-202412 | B11: 1023 | C11: 2024-12 | D11: 50 | E11: MRR | F11: 50
A12: S-1023-202501 | B12: 1023 | C12: 2025-01 | D12: 50 | E12: MRR | F12: 50
A13: S-1023-202502 | B13: 1023 | C13: 2025-02 | D13: 50 | E13: MRR | F13: 50
... A989: S-1999-202505 | B989: 1999 | C989: 2025-05 | D989: 500 | E989: MRR | F989: 500

Sheet customers_raw
A1: customer_id | B1: signup_date | C1: plan_type | D1: monthly_fee | E1: acquisition_cost | F1: churn_date
A2: 1001 | B2: 45603 | C2: Basic | D2: 50 | E2: 30
A3: 1002 | B3: 45449 | C3: Basic | D3: 50 | E3: 30
A4: 1003 | B4: 45657 | C4: Basic | D4: 50 | E4: 30
A5: 1004 | B5: 45617 | C5: Pro | D5: 200 | E5: 100
A6: 1005 | B6: 45520 | C6: Pro | D6: 200 | E6: 100
A7: 1006 | B7: 45606 | C7: Basic | D7: 50 | E7: 30
A8: 1007 | B8: 45363 | C8: Enterprise | D8: 500 | E8: 200
A9: 1008 | B9: 45605 | C9: Pro | D9: 200 | E9: 100
A10: 1009 | B10: 45520 | C10: Pro | D10: 200 | E10: 100
A11: 1010 | B11: 45754 | C11: Pro | D11: 200 | E11: 100
A12: 1011 | B12: 45747 | C12: Basic | D12: 50 | E12: 30
A13: 1012 | B13: 45712 | C13: Enterprise | D13: 500 | E13: 200
... A20: 1019 | B20: 45472 | C20: Basic | D20: 50 | E20: 30
A21: 1020 | B21: 45578 | C21: Pro | D21: 200 | E21: 100 | F21: 45785
A22: 1021 | B22: 45411 | C22: Pro | D22: 200 | E22: 100 | F22: 45464
A23: 1022 | B23: 45373 | C23: Enterprise | D23: 500 | E23: 200
A24: 1023 | B24: 45641 | C24: Basic | D24: 50 | E24: 30 | F24: 45831
A25: 1024 | B25: 45587 | C25: Basic | D25: 50 | E25: 30
A26: 1025 | B26: 45364 | C26: Enterprise | D26: 500 | E26: 200
A27: 1026 | B27: 45743 | C27: Pro | D27: 200 | E27: 100 | F27: 45818
A28: 1027 | B28: 45455 | C28: Pro | D28: 200 | E28: 100
A29: 1028 | B29: 45670 | C29: Enterprise | D29: 500 | E29: 200
A30: 1029 | B30: 45833 | C30: Enterprise | D30: 500 | E30: 200
A31: 1030 | B31: 45614 | C31: Enterprise | D31: 500 | E31: 200
A32: 1031 | B32: 45390 | C32: Pro | D32: 200 | E32: 100 | F32: 45640
A33: 1032 | B33: 45692 | C33: Pro | D33: 200 | E33: 100
A34: 1033 | B34: 45723 | C34: Basic | D34: 50 | E34: 30
A35: 1034 | B35: 45388 | C35: Basic | D35: 50 | E35: 30 | F35: 45753
A36: 1035 | B36: 45504 | C36: Basic | D36: 50 | E36: 30 | F36: 45779
A37: 1036 | B37: 45419 | C37: Enterprise | D37: 500 | E37: 200
A38: 1037 | B38: 45626 | C38: Pro | D38: 200 | E38: 100
A39: 1038 | B39: 45319 | C39: Enterprise | D39: 500 | E39: 200
A40: 1039 | B40: 45769 | C40: Basic | D40: 50 | E40: 30
A41: 1040 | B41: 45428 | C41: Enterprise | D41: 500 | E41: 200
A42: 1041 | B42: 45464 | C42: Pro | D42: 200 | E42: 100
A43: 1042 | B43: 45400 | C43: Pro | D43: 200 | E43: 100 | F43: 45735
A44: 1043 | B44: 45684 | C44: Enterprise | D44: 500 | E44: 200 | F44: 45727
A45: 1044 | B45: 45716 | C45: Pro | D45: 200 | E45: 100
A46: 1045 | B46: 45838 | C46: Pro | D46: 200 | E46: 100
...
